<?xml version="1.0" ?>
<sdf version="1.6">
  <model name="tilting_table">
    <static>false</static>

    <link name="base">
      <pose>0 0 0.05 0 0 0</pose>
      <inertial>
        <mass>1.0</mass>
        <inertia> <ixx>0.1</ixx> <ixy>0</ixy> <ixz>0</ixz> <iyy>0.1</iyy> <iyz>0</iyz> <izz>0.1</izz> </inertia>
      </inertial>
      <collision name="base_collision">
        <geometry><box><size>0.5 0.5 0.1</size></box></geometry>
      </collision>
      <visual name="base_visual">
        <geometry><box><size>0.5 0.5 0.1</size></box></geometry>
        <material><script><uri>file://media/materials/scripts/gazebo.material</uri><name>Gazebo/Grey</name></script></material>
      </visual>
    </link>

    <link name="intermediate_link">
      <pose>0 0 0.1 0 0 0</pose> <inertial>
        <mass>0.001</mass> <inertia> <ixx>1e-6</ixx> <ixy>0</ixy> <ixz>0</ixz> <iyy>1e-6</iyy> <iyz>0</iyz> <izz>1e-6</izz> </inertia>
      </inertial>
      </link>

    <link name="plate">
      <pose>0 0 ${0.02/2} 0 0 0</pose>
       <inertial>
        <mass>0.5</mass>
        <pose>0 0 0 0 0 0</pose>
        <inertia> <ixx>${0.5 / 12.0 * (0.4*0.4 + 0.02*0.02)}</ixx> <ixy>0</ixy> <ixz>0</ixz>
                 <iyy>${0.5 / 12.0 * (0.4*0.4 + 0.02*0.02)}</iyy> <iyz>0</iyz>
                 <izz>${0.5 / 12.0 * (0.4*0.4 + 0.4*0.4)}</izz> </inertia>
      </inertial>
<inertia>
          <ixx>0.006683</ixx> <ixy>0</ixy> <ixz>0</ixz>
          <iyy>0.006683</iyy> <iyz>0</iyz>
          <izz>0.013333</izz>
        </inertia>      <collision name="plate_collision">
         <pose>0 0 0 0 0 0</pose>
        <geometry><box><size>0.4 0.4 0.02</size></box></geometry>
        <surface>
          <friction>
             <ode> <mu>1.0</mu> <mu2>1.0</mu2> </ode>
          </friction>
          <contact>
             <ode> <kp>1e+8</kp> <kd>1</kd> <min_depth>0.001</min_depth> <max_vel>0.1</max_vel> </ode>
          </contact>
        </surface>
      </collision>
      <visual name="plate_visual">
         <pose>0 0 0 0 0 0</pose>
        <geometry><box><size>0.4 0.4 0.02</size></box></geometry>
        <material><script><uri>file://media/materials/scripts/gazebo.material</uri><name>Gazebo/White</name></script></material>
      </visual>
    </link>

    <joint name="joint_x" type="revolute">
      <parent>base</parent>
      <child>intermediate_link</child>
      <pose>0 0 -0.05 0 0 0</pose>
      <axis>
        <xyz>1 0 0</xyz>
        <limit> <lower>-0.5</lower> <upper>0.5</upper> <effort>10</effort> <velocity>1</velocity> </limit>
        <dynamics> <damping>0.1</damping> </dynamics>
      </axis>
      <hardwareInterface>hardware_interface/EffortJointInterface</hardwareInterface>
    </joint>

    <transmission name="tran_x">
      <type>transmission_interface/SimpleTransmission</type>
      <joint name="joint_x">
        <hardwareInterface>hardware_interface/EffortJointInterface</hardwareInterface>
      </joint>
      <actuator name="motor_x">
        <hardwareInterface>hardware_interface/EffortJointInterface</hardwareInterface>
        <mechanicalReduction>1</mechanicalReduction>
      </actuator>
    </transmission>

    <joint name="joint_y" type="revolute">
      <parent>intermediate_link</parent>
      <child>plate</child>
      <pose>0 0 -${0.02/2} 0 0 0</pose>
      <axis>
        <xyz>0 1 0</xyz>
         <limit> <lower>-0.5</lower> <upper>0.5</upper> <effort>10</effort> <velocity>1</velocity> </limit>
        <dynamics> <damping>0.1</damping> </dynamics>
      </axis>
      <hardwareInterface>hardware_interface/EffortJointInterface</hardwareInterface>
    </joint>

    <transmission name="tran_y">
      <type>transmission_interface/SimpleTransmission</type>
      <joint name="joint_y">
        <hardwareInterface>hardware_interface/EffortJointInterface</hardwareInterface>
      </joint>
      <actuator name="motor_y">
        <hardwareInterface>hardware_interface/EffortJointInterface</hardwareInterface>
        <mechanicalReduction>1</mechanicalReduction>
      </actuator>
    </transmission>

    <gazebo>
      <plugin name="gazebo_ros_control" filename="libgazebo_ros_control.so">
        <robotNamespace>/table_1</robotNamespace>
      </plugin>
    </gazebo>

  </model>
</sdf>
